
# These are the steps without flask

pip install -r requirements.txt

rename example.env to .env

!python ingest.py

pip3 install python-dotenv urllib3 chardet xformers pysqlite3-binary transformers accelerate scipy sentence_transformers flask --ignore-installed blinker==1.4

pip install --upgrade langchain

# pip install -qU \
    #transformers==4.31.0 \
    #accelerate==0.21.0 \
    #einops==0.6.1 \
    #langchain==0.0.240 \
    #xformers==0.0.20 \
   # bitsandbytes==0.41.0
 

pip install -qU transformers==4.31.0 accelerate==0.21.0 einops==0.6.1 langchain==0.0.240 xformers==0.0.20 bitsandbytes==0.41.0

python chat.py



###after running the app.py 
pip uninstall psutil
pip install --upgrade psutil



If this error comes

Exception occurred: Traceback (most recent call last):
  File "/home/adillssayed/TeddyBot-main/app.py", line 18, in chat
    response = techgpt.run_model(message, model_app)
  File "/home/adillssayed/TeddyBot-main/techgpt.py", line 213, in run_model
    llm_open = ChatOpenAI(model_name=model_name)
  File "/opt/conda/lib/python3.10/site-packages/langchain/load/serializable.py", line 74, in __init__
    super().__init__(**kwargs)
  File "pydantic/main.py", line 341, in pydantic.main.BaseModel.__init__
pydantic.error_wrappers.ValidationError: 1 validation error for ChatOpenAI
__root__
  `openai` has no `ChatCompletion` attribute, this is likely due to an old version of the openai package. Try upgrading it with `pip install --upgrade openai`. (type=value_error)

then install 
- pip install openai==0.28.0

pip install wikipedia



